<?xml version="1.0" ?>
<robot name="kr10_arm">

<material name="silver"><color rgba="0.700 0.700 0.700 1.000"/></material>
<material name="black"><color rgba="0.0 0.0 0.0 1.0"/></material>
<material name="white"><color rgba="1.0 1.0 1.0 1.0"/></material>
<material name="orange"><color rgba="1.0 0.55 0.0 1.0"/></material>



<link name="base_link">
  <inertial>
    <origin xyz="0.1861831360940044 -0.1594996180691991 -0.5579340066762665" rpy="0 0 0"/>
    <mass value="94.29951890589429"/>
    <inertia ixx="1.096073" iyy="0.950065" izz="0.756536" ixy="-6.6e-05" iyz="0.044667" ixz="-0.000823"/>
  </inertial>
  <visual>
    <origin xyz="0 0 0" rpy="0 0 0"/>
    <geometry>
      <mesh filename="meshes/base_link.stl" scale="0.001 0.001 0.001"/>
    </geometry>
    <material name="silver"/>
  </visual>
  <collision>
    <origin xyz="0 0 0" rpy="0 0 0"/>
    <geometry>
      <mesh filename="meshes/base_link.stl" scale="0.001 0.001 0.001"/>
    </geometry>
  </collision>
</link>

<link name="KR10_R1100_sixx_CR_01_1">
  <inertial>
    <origin xyz="0.0075937763392029956 0.10872078233873679 0.0031484004455062387" rpy="0 0 0"/>
    <mass value="49.25911454345063"/>
    <inertia ixx="0.524901" iyy="0.441697" izz="0.466428" ixy="-0.035774" iyz="-0.021658" ixz="0.09829"/>
  </inertial>
  <visual>
    <origin xyz="-0.186226 0.031 0.519026" rpy="0 0 0"/>
    <geometry>
      <mesh filename="meshes/KR10_R1100_sixx_CR_01_1.stl" scale="0.001 0.001 0.001"/>
    </geometry>
    <material name="silver"/>
  </visual>
  <collision>
    <origin xyz="-0.186226 0.031 0.519026" rpy="0 0 0"/>
    <geometry>
      <mesh filename="meshes/KR10_R1100_sixx_CR_01_1.stl" scale="0.001 0.001 0.001"/>
    </geometry>
  </collision>
</link>

<link name="end_effector_v1_1">
  <inertial>
    <origin xyz="-0.032871420104439275 0.015252527654309178 -0.015446971688058364" rpy="0 0 0"/>
    <mass value="5.440109388516065"/>
    <inertia ixx="0.019276" iyy="0.006466" izz="0.022179" ixy="-0.006718" iyz="-0.000872" ixz="-0.000414"/>
  </inertial>
  <visual>
    <origin xyz="-0.188786 -1.272182 0.498821" rpy="0 0 0"/>
    <geometry>
      <mesh filename="meshes/end_effector_v1_1.stl" scale="0.001 0.001 0.001"/>
    </geometry>
    <material name="silver"/>
  </visual>
  <collision>
    <origin xyz="-0.188786 -1.272182 0.498821" rpy="0 0 0"/>
    <geometry>
      <mesh filename="meshes/end_effector_v1_1.stl" scale="0.001 0.001 0.001"/>
    </geometry>
  </collision>
</link>

<link name="KR10_R1100_sixx_CR_05_1">
  <inertial>
    <origin xyz="-0.052273687091675736 -0.003622808003135969 0.03136390813901768" rpy="0 0 0"/>
    <mass value="3.6259199733283825"/>
    <inertia ixx="0.014546" iyy="0.064109" izz="0.070711" ixy="-0.022193" iyz="0.004948" ixz="0.011233"/>
  </inertial>
  <visual>
    <origin xyz="-0.27203 -1.242782 0.502762" rpy="0 0 0"/>
    <geometry>
      <mesh filename="meshes/KR10_R1100_sixx_CR_05_1.stl" scale="0.001 0.001 0.001"/>
    </geometry>
    <material name="silver"/>
  </visual>
  <collision>
    <origin xyz="-0.27203 -1.242782 0.502762" rpy="0 0 0"/>
    <geometry>
      <mesh filename="meshes/KR10_R1100_sixx_CR_05_1.stl" scale="0.001 0.001 0.001"/>
    </geometry>
  </collision>
</link>

<link name="Wrist_1">
  <inertial>
    <origin xyz="0.022305924738296373 0.15724826781260837 0.01659202684949196" rpy="0 0 0"/>
    <mass value="30.07522579715273"/>
    <inertia ixx="0.298804" iyy="0.081447" izz="0.283216" ixy="-0.034281" iyz="-0.021395" ixz="0.008346"/>
  </inertial>
  <visual>
    <origin xyz="-0.210802 -0.934612 0.500681" rpy="0 0 0"/>
    <geometry>
      <mesh filename="meshes/Wrist_1.stl" scale="0.001 0.001 0.001"/>
    </geometry>
    <material name="silver"/>
  </visual>
  <collision>
    <origin xyz="-0.210802 -0.934612 0.500681" rpy="0 0 0"/>
    <geometry>
      <mesh filename="meshes/Wrist_1.stl" scale="0.001 0.001 0.001"/>
    </geometry>
  </collision>
</link>

<link name="KR10_R1100_sixx_CR_03_1">
  <inertial>
    <origin xyz="-0.0457620299374957 0.05739141289916183 0.050049441960306806" rpy="0 0 0"/>
    <mass value="30.34731102117061"/>
    <inertia ixx="0.235465" iyy="0.072065" izz="0.237362" ixy="0.004053" iyz="0.003001" ixz="-0.003305"/>
  </inertial>
  <visual>
    <origin xyz="-0.246637 -0.705 0.558163" rpy="0 0 0"/>
    <geometry>
      <mesh filename="meshes/KR10_R1100_sixx_CR_03_1.stl" scale="0.001 0.001 0.001"/>
    </geometry>
    <material name="silver"/>
  </visual>
  <collision>
    <origin xyz="-0.246637 -0.705 0.558163" rpy="0 0 0"/>
    <geometry>
      <mesh filename="meshes/KR10_R1100_sixx_CR_03_1.stl" scale="0.001 0.001 0.001"/>
    </geometry>
  </collision>
</link>

<link name="KR10_R1100_sixx_CR_02_1">
  <inertial>
    <origin xyz="0.026283115697211784 0.2612232849568521 -0.049126520112941885" rpy="0 0 0"/>
    <mass value="78.8587590799443"/>
    <inertia ixx="3.563213" iyy="0.350244" izz="3.521824" ixy="0.003039" iyz="0.011596" ixz="0.06619"/>
  </inertial>
  <visual>
    <origin xyz="-0.170668 -0.145 0.45639" rpy="0 0 0"/>
    <geometry>
      <mesh filename="meshes/KR10_R1100_sixx_CR_02_1.stl" scale="0.001 0.001 0.001"/>
    </geometry>
    <material name="silver"/>
  </visual>
  <collision>
    <origin xyz="-0.170668 -0.145 0.45639" rpy="0 0 0"/>
    <geometry>
      <mesh filename="meshes/KR10_R1100_sixx_CR_02_1.stl" scale="0.001 0.001 0.001"/>
    </geometry>
  </collision>
</link>

<joint name="joint_1" type="revolute">
  <origin xyz="0.186226 -0.031 -0.519026" rpy="0 0 0"/>
  <parent link="base_link"/>
  <child link="KR10_R1100_sixx_CR_01_1"/>
  <axis xyz="-0.0 1.0 0.0"/>
  <limit upper="1.396263" lower="-4.537856" effort="100" velocity="100"/>
</joint>

<joint name="joint_6" type="revolute">
  <origin xyz="-0.083244 0.0294 0.003941" rpy="0 0 0"/>
  <parent link="KR10_R1100_sixx_CR_05_1"/>
  <child link="end_effector_v1_1"/>
  <axis xyz="0.834422 -0.387224 0.39217"/>
  <limit upper="6.108652" lower="-6.108652" effort="100" velocity="100"/>
</joint>

<joint name="joint_5" type="revolute">
  <origin xyz="0.061228 0.30817 -0.002081" rpy="0 0 0"/>
  <parent link="Wrist_1"/>
  <child link="KR10_R1100_sixx_CR_05_1"/>
  <axis xyz="-0.437807 -0.033503 0.898444"/>
  <limit upper="2.094395" lower="-2.094395" effort="100" velocity="100"/>
</joint>

<joint name="joint_4" type="revolute">
  <origin xyz="-0.035835 0.229612 0.057482" rpy="0 0 0"/>
  <parent link="KR10_R1100_sixx_CR_03_1"/>
  <child link="Wrist_1"/>
  <axis xyz="0.141622 0.98426 0.105715"/>
  <limit upper="3.228859" lower="-3.228859" effort="100" velocity="100"/>
</joint>

<joint name="joint_3" type="revolute">
  <origin xyz="0.075969 0.56 -0.101773" rpy="0 0 0"/>
  <parent link="KR10_R1100_sixx_CR_02_1"/>
  <child link="KR10_R1100_sixx_CR_03_1"/>
  <axis xyz="-0.598183 -0.0 0.80136"/>
  <limit upper="3.665191" lower="-1.151917" effort="100" velocity="100"/>
</joint>

<joint name="joint_2" type="revolute">
  <origin xyz="-0.015558 0.176 0.062636" rpy="0 0 0"/>
  <parent link="KR10_R1100_sixx_CR_01_1"/>
  <child link="KR10_R1100_sixx_CR_02_1"/>
  <axis xyz="0.598183 0.0 -0.80136"/>
  <limit upper="2.356194" lower="-1.745329" effort="100" velocity="100"/>
</joint>

</robot>
